Workbook

Sheet raw_data
A1: Vendor_ID | B1: Vendor_Name | C1: Category | D1: Country | E1: Region | F1: Status | G1: Onboarding_Date | H1: Last_Updated | I1: Contact_Email | J1: Account_Code | K1: Data_Source | L1: Verified_By | M1: Record_Status
A2: VND-0789 | B2: Vendor Zeta 901 | C2: Marketing | D2: Canada | E2: AMER | F2: Active | G2: 43604 | H2: 43744 | I2: vendor.zeta.901@gmail.com | J2: ACC-9055 | K2: Legacy System | M2: Clean
A3: VND-0441 | B3: Vendor Epsilon 150 | C3: Marketing | D3: India | E3: APAC | F3: Active | G3: 44674 | H3: 44778 | I3: vendor.epsilon.150@corp.net | J3: ACC-1529 | K3: Manual Entry | L3: James T. | M3: Clean
A4: VND-0140 | B4: Vendor Omega 114 | C4: Finance | D4: Singapore | E4: APAC | F4: Active | G4: 45459 | H4: 45728 | I4: vendor.omega.114@outlook.com | J4: ACC-1744 | K4: Oracle | L4: James T. | M4: Clean
A5: VND-0696 | B5: Vendor Prime 56 | C5: HR | D5: USA | E5: AMER | F5: Active | G5: 45329 | H5: 45420 | I5: vendor.prime.56@vendor.com | J5: ACC-7119 | K5: Oracle | L5: James T. | M5: Clean
A6: VND-0067 | B6: Vendor Zeta 71 | C6: Operations | D6: Singapore | E6: APAC | F6: Active | G6: 45186 | H6: 45436 | I6: vendor.zeta.71@gmail.com | J6: ACC-8102 | K6: Manual Entry | M6: Clean
A7: VND-0853 | B7: Vendor Beta 524 | C7: Operations | D7: UK | E7: EMEA | F7: Active | G7: 44121 | H7: 44132 | I7: vendor.beta.524@gmail.com | J7: ACC-9846 | K7: Manual Entry | L7: Ravi K. | M7: Clean
A8: VND-0406 | B8: Vendor Services 899 | C8: Finance | D8: UK | E8: EMEA | F8: Active | G8: 45037 | H8: 45294 | I8: vendor.services.899@corp.net | J8: ACC-6015 | K8: Oracle | L8: Priya S. | M8: Clean
A9: VND-0737 | B9: Vendor Omega 652 | C9: Finance | D9: India | E9: APAC | F9: Active | G9: 45635 | H9: 45962 | I9: vendor.omega.652@gmail.com | J9: ACC-9419 | K9: Oracle | M9: Clean
A10: VND-0458 | B10: Vendor Corp 75 | C10: Finance | D10: Australia | E10: APAC | F10: Active | G10: 44700 | H10: 45010 | I10: vendor.corp.75@gmail.com | J10: ACC-5612 | K10: Legacy System | L10: James T. | M10: Clean
A11: VND-0308 | B11: Vendor Ltd 699 | C11: Marketing | D11: India | E11: EMEA | F11: Active | G11: 45348 | H11: 45356 | I11: vendor.ltd.699@gmail.com | J11: ACC-3588 | K11: Legacy System | L11: James T. | M11: Clean
A12: VND-0440 | B12: Vendor Global 110 | C12: IT | D12: Germany | E12: EMEA | F12: Active | G12: 43697 | H12: 43799 | I12: vendor.global.110@outlook.com | J12: ACC-3636 | K12: Manual Entry | M12: Clean
A13: VND-0068 | B13: Vendor Ltd 849 | C13: it | D13: Singapore | E13: APAC | F13: Active | G13: 44187 | H13: 44454 | I13: vendor.ltd.849@outlook.com | J13: ACC-9817 | K13: Legacy System | L13: James T. | M13: Clean
A14: VND-0651 | B14: Vendor Tech 494 | C14: Legal | D14: India | E14: APAC | F14: Active | G14: 45622 | H14: 45765 | I14: vendor.tech.494@vendor.com | J14: ACC-9469 | K14: SAP | L14: Sarah L. | M14: Clean
A15: VND-0874 | B15: Vendor Corp 541 | C15: Finance | D15: Germany | E15: EMEA | F15: Active | G15: 43935 | H15: 43985 | I15: vendor.corp.541@corp.net | J15: ACC-3755 | K15: Manual Entry | L15: Ravi K. | M15: Clean
A16: VND-0491 | B16: Vendor Gamma 437 | C16: Legal | D16: Australia | E16: APAC | F16: Active | G16: 45200 | H16: 45489 | I16: vendor.gamma.437@outlook.com | J16: ACC-5514 | K16: Legacy System | L16: Ravi K. | M16: Clean
A17: VND-0943 | B17: Vendor Alpha 246 | C17: Marketing | D17: USA | E17: AMER | F17: Active | G17: 44661 | H17: 45002 | I17: vendor.alpha.246@gmail.com | J17: ACC-4559 | K17: Legacy System | L17: James T. | M17: Clean
A18: VND-0077 | B18: Vendor Epsilon 15 | C18: Legal | D18: Australia | E18: APAC | F18: Active | G18: 43652 | H18: 43679 | I18: vendor.epsilon.15@corp.net | J18: ACC-5786 | K18: Oracle | M18: Clean
A19: VND-0434 | B19: Vendor Alpha 544 | C19: Legal | D19: India | E19: APAC | F19: Active | G19: 45238 | H19: 45537 | I19: vendor.alpha.544@vendor.com | J19: ACC-9328 | K19: Oracle | M19: Clean
A20: VND-0533 | B20: Vendor Zeta 194 | C20: HR | D20: Australia | E20: APAC | F20: Active | G20: 44489 | H20: 44572 | I20: vendor.zeta.194@vendor.com | J20: ACC-7199 | K20: Oracle | L20: Anita M. | M20: Clean
A21: VND-0875 | B21: Vendor Gamma 262 | C21: Marketing | D21: India | E21: AMER | F21: Active | G21: 45134 | H21: 45481 | I21: vendor.gamma.262@yahoo.com | J21: ACC-1965 | K21: Manual Entry | L21: Ravi K. | M21: Clean
A22: VND-0724 | B22: Vendor Solutions 565 | C22: IT | D22: UK | E22: EMEA | F22: Active | G22: 44368 | H22: 44596 | I22: vendor.solutions.565@outlook.com | J22: ACC-2515 | K22: Manual Entry | L22: Priya S. | M22: Clean
A23: VND-0667 | B23: Vendor Solutions 125 | C23: Legal | D23: India | E23: APAC | F23: Active | G23: 43998 | H23: 44190 | I23: vendor.solutions.125@corp.net | J23: ACC-4027 | K23: SAP | M23: Clean
A24: VND-0602 | B24: Vendor Group 730 | C24: IT | D24: Germany | E24: EMEA | F24: Active | G24: 44270 | H24: 45440 | I24: vendor.group.730@yahoo.com | J24: ACC-2926 | K24: Oracle | L24: Ravi K. | M24: Clean
A25: VND-0704 | B25: Vendor Solutions 93 | C25: IT | D25: Germany | E25: EMEA | F25: Active | G25: 44128 | H25: 44488 | I25: vendor.solutions.93@vendor.com | J25: ACC-1399 | K25: Legacy System | L25: James T. | M25: Clean
A26: VND-0866 | B26: Vendor Corp 758 | C26: HR | D26: India | E26: APAC | F26: Active | G26: 44894 | H26: 44928 | I26: vendor.corp.758@gmail.com | J26: ACC-7841 | K26: Legacy System | L26: Sarah L. | M26: Clean
A27: VND-0912 | B27: Vendor Tech 935 | C27: Marketing | D27: UK | E27: EMEA | F27: Active | G27: 43587 | H27: 43688 | I27: vendor.tech.935@yahoo.com | J27: ACC-5654 | K27: Oracle | L27: Ravi K. | M27: Clean
A28: VND-0360 | B28: Vendor Solutions 604 | C28: Marketing | D28: USA | E28: AMER | F28: Active | G28: 44672 | H28: 44737 | I28: vendor.solutions.604@yahoo.com | J28: ACC-1029 | K28: Legacy System | L28: Sarah L. | M28: Clean
A29: VND-0315 | B29: Vendor Delta 644 | C29: Legal | D29: USA | E29: AMER | F29: Under Review | G29: 45278 | H29: 45389 | I29: vendor.delta.644@gmail.com | J29: ACC-2646 | K29: Oracle | L29: Priya S. | M29: Clean
A30: VND-0763 | B30: Vendor Omega 138 | C30: Finance | D30: Singapore | E30: APAC | F30: Active | G30: 43914 | H30: 44205 | I30: vendor.omega.138@vendor.com | J30: ACC-9837 | K30: Legacy System | L30: James T. | M30: Clean
A31: VND-0862 | B31: Vendor Prime 133 | C31: Legal | D31: Australia | E31: APAC | F31: Inactive | G31: 43949 | H31: 44304 | I31: vendor.prime.133@yahoo.com | J31: ACC-8461 | K31: Legacy System | L31: Priya S. | M31: Clean
A32: VND-0024 | B32: Vendor Ltd 772 | C32: Marketing | D32: USA | E32: AMER | F32: Active | G32: 45455 | H32: 45701 | I32: vendor.ltd.772@yahoo.com | J32: ACC-7570 | K32: SAP | L32: Ravi K. | M32: Clean
A33: VND-0031 | B33: Vendor Delta 519 | C33: Finance | D33: USA | E33: AMER | F33: Under Review | G33: 43747 | H33: 43872 | I33: vendor.delta.519@outlook.com | J33: ACC-5669 | K33: Oracle | L33: James T. | M33: Clean
A34: VND-0539 | B34: Vendor Alpha 273 | C34: Marketing | D34: Germany | E34: EMEA | F34: Active | G34: 45391 | H34: 45483 | I34: vendor.alpha.273@yahoo.com | J34: ACC-5097 | K34: Legacy System | L34: Priya S. | M34: Clean
A35: VND-0534 | B35: Vendor Beta 433 | C35: Legal | D35: USA | E35: AMER | F35: Active | G35: 44579 | H35: 44724 | I35: noatsign.com | J35: ACC-5404 | K35: Legacy System | L35: Ravi K. | M35: Clean
A36: VND-0219 | B36: Vendor Solutions 790 | C36: Logistics | D36: India | E36: APAC | F36: Under Review | G36: 44112 | H36: 44320 | J36: ACC-8822 | K36: Oracle | L36: Anita M. | M36: Clean
A37: VND-0443 | B37: Vendor Group 816 | C37: Marketing | D37: Singapore | E37: APAC | F37: Active | G37: 43658 | H37: 43853 | I37: vendor.group.816@vendor.com | J37: ACC-7825 | K37: Manual Entry | L37: Sarah L. | M37: Clean
A38: VND-0089 | B38: Vendor Tech 447 | C38: Legal | D38: Canada | E38: AMER | F38: Active | G38: 43839 | H38: 44079 | I38: vendor.tech.447@outlook.com | J38: ACC-7690 | K38: Manual Entry | L38: Anita M. | M38: Clean
A39: VND-0319 | B39: Vendor Solutions 609 | C39: IT | D39: Australia | E39: APAC | F39: Inactive | G39: 43515 | H39: 43699 | I39: vendor.solutions.609@outlook.com | J39: ACC-3162 | K39: Legacy System | L39: Sarah L. | M39: Clean
A40: VND-0540 | B40: Vendor Beta 998 | C40: Marketing | D40: Singapore | E40: APAC | F40: Active | G40: 45280 | H40: 45406 | I40: vendor.beta.998@gmail.com | J40: ACC-4263 | K40: Legacy System | M40: Clean
...

Sheet validated_data
A1: Vendor_ID | B1: Vendor_Name | C1: Category | D1: Country | E1: Region | F1: Status | G1: Onboarding_Date | H1: Last_Updated | I1: Contact_Email | J1: Account_Code | K1: Data_Source | L1: Verified_By | M1: Record_Status | N1: Validation_Status | O1: Issues_Found | P1: Action_Taken | Q1: email_valid
A2: VND-0789 | B2: Vendor Zeta 901 | C2: Marketing | D2: Canada | E2: AMER | F2: Active | G2: 43604 | H2: 43744 | I2: vendor.zeta.901@gmail.com | J2: ACC-9055 | K2: Legacy System | M2: Flagged for Review | N2: =IF(OR(B2="",H2="",I2="",J2="",L2="",Q2="Invalid"),"Flagged","Clean") -> Flagged | O2: =TRIM(IF(B2="","Missing Vendor_Name ","")&IF(I2="","Missing Contact_Email ","")&IF(J2="","Missing Account_Code ","")&IF(L2="","Missing Verified_By ","")&IF(Q2="Invalid","Invalid Email Format ","")&IF(H2="","Missing Last_Updated ","")) -> Missing Verified_By | P2: =IF(N2="Clean","Clean","Flagged for Review") -> Flagged for Review | Q2: =IF(I2="","Blank",IF(ISERROR(FIND("@",I2&"")),"Invalid",IF(FIND("@",I2&"")<2,"Invalid",IF(LEN(I2&"")-FIND("@",I2&"")<4,"Invalid","Valid")))) -> Valid
A3: VND-0441 | B3: Vendor Epsilon 150 | C3: Marketing | D3: India | E3: APAC | F3: Active | G3: 44674 | H3: 44778 | I3: vendor.epsilon.150@corp.net | J3: ACC-1529 | K3: Manual Entry | L3: James T. | M3: Clean | N3: =IF(OR(B3="",H3="",I3="",J3="",L3="",Q3="Invalid"),"Flagged","Clean") -> Clean | O3: =TRIM(IF(B3="","Missing Vendor_Name ","")&IF(I3="","Missing Contact_Email ","")&IF(J3="","Missing Account_Code ","")&IF(L3="","Missing Verified_By ","")&IF(Q3="Invalid","Invalid Email Format ","")&IF(H3="","Missing Last_Updated ","")) | P3: =IF(N3="Clean","Clean","Flagged for Review") -> Clean | Q3: =IF(I3="","Blank",IF(ISERROR(FIND("@",I3&"")),"Invalid",IF(FIND("@",I3&"")<2,"Invalid",IF(LEN(I3&"")-FIND("@",I3&"")<4,"Invalid","Valid")))) -> Valid
A4: VND-0140 | B4: Vendor Omega 114 | C4: Finance | D4: Singapore | E4: APAC | F4: Active | G4: 45459 | H4: 45728 | I4: vendor.omega.114@outlook.com | J4: ACC-1744 | K4: Oracle | L4: James T. | M4: Clean | N4: =IF(OR(B4="",H4="",I4="",J4="",L4="",Q4="Invalid"),"Flagged","Clean") -> Clean | O4: =TRIM(IF(B4="","Missing Vendor_Name ","")&IF(I4="","Missing Contact_Email ","")&IF(J4="","Missing Account_Code ","")&IF(L4="","Missing Verified_By ","")&IF(Q4="Invalid","Invalid Email Format ","")&IF(H4="","Missing Last_Updated ","")) | P4: =IF(N4="Clean","Clean","Flagged for Review") -> Clean | Q4: =IF(I4="","Blank",IF(ISERROR(FIND("@",I4&"")),"Invalid",IF(FIND("@",I4&"")<2,"Invalid",IF(LEN(I4&"")-FIND("@",I4&"")<4,"Invalid","Valid")))) -> Valid
A5: VND-0696 | B5: Vendor Prime 56 | C5: HR | D5: USA | E5: AMER | F5: Active | G5: 45329 | H5: 45420 | I5: vendor.prime.56@vendor.com | J5: ACC-7119 | K5: Oracle | L5: James T. | M5: Clean | N5: =IF(OR(B5="",H5="",I5="",J5="",L5="",Q5="Invalid"),"Flagged","Clean") -> Clean | O5: =TRIM(IF(B5="","Missing Vendor_Name ","")&IF(I5="","Missing Contact_Email ","")&IF(J5="","Missing Account_Code ","")&IF(L5="","Missing Verified_By ","")&IF(Q5="Invalid","Invalid Email Format ","")&IF(H5="","Missing Last_Updated ","")) | P5: =IF(N5="Clean","Clean","Flagged for Review") -> Clean | Q5: =IF(I5="","Blank",IF(ISERROR(FIND("@",I5&"")),"Invalid",IF(FIND("@",I5&"")<2,"Invalid",IF(LEN(I5&"")-FIND("@",I5&"")<4,"Invalid","Valid")))) -> Valid
A6: VND-0067 | B6: Vendor Zeta 71 | C6: Operations | D6: Singapore | E6: APAC | F6: Active | G6: 45186 | H6: 45436 | I6: vendor.zeta.71@gmail.com | J6: ACC-8102 | K6: Manual Entry | M6: Flagged for Review | N6: =IF(OR(B6="",H6="",I6="",J6="",L6="",Q6="Invalid"),"Flagged","Clean") -> Flagged | O6: =TRIM(IF(B6="","Missing Vendor_Name ","")&IF(I6="","Missing Contact_Email ","")&IF(J6="","Missing Account_Code ","")&IF(L6="","Missing Verified_By ","")&IF(Q6="Invalid","Invalid Email Format ","")&IF(H6="","Missing Last_Updated ","")) -> Missing Verified_By | P6: =IF(N6="Clean","Clean","Flagged for Review") -> Flagged for Review | Q6: =IF(I6="","Blank",IF(ISERROR(FIND("@",I6&"")),"Invalid",IF(FIND("@",I6&"")<2,"Invalid",IF(LEN(I6&"")-FIND("@",I6&"")<4,"Invalid","Valid")))) -> Valid
A7: VND-0853 | B7: Vendor Beta 524 | C7: Operations | D7: UK | E7: EMEA | F7: Active | G7: 44121 | H7: 44132 | I7: vendor.beta.524@gmail.com | J7: ACC-9846 | K7: Manual Entry | L7: Ravi K. | M7: Clean | N7: =IF(OR(B7="",H7="",I7="",J7="",L7="",Q7="Invalid"),"Flagged","Clean") -> Clean | O7: =TRIM(IF(B7="","Missing Vendor_Name ","")&IF(I7="","Missing Contact_Email ","")&IF(J7="","Missing Account_Code ","")&IF(L7="","Missing Verified_By ","")&IF(Q7="Invalid","Invalid Email Format ","")&IF(H7="","Missing Last_Updated ","")) | P7: =IF(N7="Clean","Clean","Flagged for Review") -> Clean | Q7: =IF(I7="","Blank",IF(ISERROR(FIND("@",I7&"")),"Invalid",IF(FIND("@",I7&"")<2,"Invalid",IF(LEN(I7&"")-FIND("@",I7&"")<4,"Invalid","Valid")))) -> Valid
A8: VND-0406 | B8: Vendor Services 899 | C8: Finance | D8: UK | E8: EMEA | F8: Active | G8: 45037 | H8: 45294 | I8: vendor.services.899@corp.net | J8: ACC-6015 | K8: Oracle | L8: Priya S. | M8: Clean | N8: =IF(OR(B8="",H8="",I8="",J8="",L8="",Q8="Invalid"),"Flagged","Clean") -> Clean | O8: =TRIM(IF(B8="","Missing Vendor_Name ","")&IF(I8="","Missing Contact_Email ","")&IF(J8="","Missing Account_Code ","")&IF(L8="","Missing Verified_By ","")&IF(Q8="Invalid","Invalid Email Format ","")&IF(H8="","Missing Last_Updated ","")) | P8: =IF(N8="Clean","Clean","Flagged for Review") -> Clean | Q8: =IF(I8="","Blank",IF(ISERROR(FIND("@",I8&"")),"Invalid",IF(FIND("@",I8&"")<2,"Invalid",IF(LEN(I8&"")-FIND("@",I8&"")<4,"Invalid","Valid")))) -> Valid
A9: VND-0737 | B9: Vendor Omega 652 | C9: Finance | D9: India | E9: APAC | F9: Active | G9: 45635 | H9: 45962 | I9: vendor.omega.652@gmail.com | J9: ACC-9419 | K9: Oracle | M9: Flagged for Review | N9: =IF(OR(B9="",H9="",I9="",J9="",L9="",Q9="Invalid"),"Flagged","Clean") -> Flagged | O9: =TRIM(IF(B9="","Missing Vendor_Name ","")&IF(I9="","Missing Contact_Email ","")&IF(J9="","Missing Account_Code ","")&IF(L9="","Missing Verified_By ","")&IF(Q9="Invalid","Invalid Email Format ","")&IF(H9="","Missing Last_Updated ","")) -> Missing Verified_By | P9: =IF(N9="Clean","Clean","Flagged for Review") -> Flagged for Review | Q9: =IF(I9="","Blank",IF(ISERROR(FIND("@",I9&"")),"Invalid",IF(FIND("@",I9&"")<2,"Invalid",IF(LEN(I9&"")-FIND("@",I9&"")<4,"Invalid","Valid")))) -> Valid
A10: VND-0458 | B10: Vendor Corp 75 | C10: Finance | D10: Australia | E10: APAC | F10: Active | G10: 44700 | H10: 45010 | I10: vendor.corp.75@gmail.com | J10: ACC-5612 | K10: Legacy System | L10: James T. | M10: Clean | N10: =IF(OR(B10="",H10="",I10="",J10="",L10="",Q10="Invalid"),"Flagged","Clean") -> Clean | O10: =TRIM(IF(B10="","Missing Vendor_Name ","")&IF(I10="","Missing Contact_Email ","")&IF(J10="","Missing Account_Code ","")&IF(L10="","Missing Verified_By ","")&IF(Q10="Invalid","Invalid Email Format ","")&IF(H10="","Missing Last_Updated ","")) | P10: =IF(N10="Clean","Clean","Flagged for Review") -> Clean | Q10: =IF(I10="","Blank",IF(ISERROR(FIND("@",I10&"")),"Invalid",IF(FIND("@",I10&"")<2,"Invalid",IF(LEN(I10&"")-FIND("@",I10&"")<4,"Invalid","Valid")))) -> Valid
A11: VND-0308 | B11: Vendor Ltd 699 | C11: Marketing | D11: India | E11: APAC | F11: Active | G11: 45348 | H11: 45356 | I11: vendor.ltd.699@gmail.com | J11: ACC-3588 | K11: Legacy System | L11: James T. | M11: Clean | N11: =IF(OR(B11="",H11="",I11="",J11="",L11="",Q11="Invalid"),"Flagged","Clean") -> Clean | O11: =TRIM(IF(B11="","Missing Vendor_Name ","")&IF(I11="","Missing Contact_Email ","")&IF(J11="","Missing Account_Code ","")&IF(L11="","Missing Verified_By ","")&IF(Q11="Invalid","Invalid Email Format ","")&IF(H11="","Missing Last_Updated ","")) | P11: =IF(N11="Clean","Clean","Flagged for Review") -> Clean | Q11: =IF(I11="","Blank",IF(ISERROR(FIND("@",I11&"")),"Invalid",IF(FIND("@",I11&"")<2,"Invalid",IF(LEN(I11&"")-FIND("@",I11&"")<4,"Invalid","Valid")))) -> Valid
A12: VND-0440 | B12: Vendor Global 110 | C12: IT | D12: Germany | E12: EMEA | F12: Active | G12: 43697 | H12: 43799 | I12: vendor.global.110@outlook.com | J12: ACC-3636 | K12: Manual Entry | M12: Flagged for Review | N12: =IF(OR(B12="",H12="",I12="",J12="",L12="",Q12="Invalid"),"Flagged","Clean") -> Flagged | O12: =TRIM(IF(B12="","Missing Vendor_Name ","")&IF(I12="","Missing Contact_Email ","")&IF(J12="","Missing Account_Code ","")&IF(L12="","Missing Verified_By ","")&IF(Q12="Invalid","Invalid Email Format ","")&IF(H12="","Missing Last_Updated ","")) -> Missing Verified_By | P12: =IF(N12="Clean","Clean","Flagged for Review") -> Flagged for Review | Q12: =IF(I12="","Blank",IF(ISERROR(FIND("@",I12&"")),"Invalid",IF(FIND("@",I12&"")<2,"Invalid",IF(LEN(I12&"")-FIND("@",I12&"")<4,"Invalid","Valid")))) -> Valid
A13: VND-0068 | B13: Vendor Ltd 849 | C13: IT | D13: Singapore | E13: APAC | F13: Active | G13: 44187 | H13: 44454 | I13: vendor.ltd.849@outlook.com | J13: ACC-9817 | K13: Legacy System | L13: James T. | M13: Clean | N13: =IF(OR(B13="",H13="",I13="",J13="",L13="",Q13="Invalid"),"Flagged","Clean") -> Clean | O13: =TRIM(IF(B13="","Missing Vendor_Name ","")&IF(I13="","Missing Contact_Email ","")&IF(J13="","Missing Account_Code ","")&IF(L13="","Missing Verified_By ","")&IF(Q13="Invalid","Invalid Email Format ","")&IF(H13="","Missing Last_Updated ","")) | P13: =IF(N13="Clean","Clean","Flagged for Review") -> Clean | Q13: =IF(I13="","Blank",IF(ISERROR(FIND("@",I13&"")),"Invalid",IF(FIND("@",I13&"")<2,"Invalid",IF(LEN(I13&"")-FIND("@",I13&"")<4,"Invalid","Valid")))) -> Valid
A14: VND-0651 | B14: Vendor Tech 494 | C14: Legal | D14: India | E14: APAC | F14: Active | G14: 45622 | H14: 45765 | I14: vendor.tech.494@vendor.com | J14: ACC-9469 | K14: SAP | L14: Sarah L. | M14: Clean | N14: =IF(OR(B14="",H14="",I14="",J14="",L14="",Q14="Invalid"),"Flagged","Clean") -> Clean | O14: =TRIM(IF(B14="","Missing Vendor_Name ","")&IF(I14="","Missing Contact_Email ","")&IF(J14="","Missing Account_Code ","")&IF(L14="","Missing Verified_By ","")&IF(Q14="Invalid","Invalid Email Format ","")&IF(H14="","Missing Last_Updated ","")) | P14: =IF(N14="Clean","Clean","Flagged for Review") -> Clean | Q14: =IF(I14="","Blank",IF(ISERROR(FIND("@",I14&"")),"Invalid",IF(FIND("@",I14&"")<2,"Invalid",IF(LEN(I14&"")-FIND("@",I14&"")<4,"Invalid","Valid")))) -> Valid
A15: VND-0874 | B15: Vendor Corp 541 | C15: Finance | D15: Germany | E15: EMEA | F15: Active | G15: 43935 | H15: 43985 | I15: vendor.corp.541@corp.net | J15: ACC-3755 | K15: Manual Entry | L15: Ravi K. | M15: Clean | N15: =IF(OR(B15="",H15="",I15="",J15="",L15="",Q15="Invalid"),"Flagged","Clean") -> Clean | O15: =TRIM(IF(B15="","Missing Vendor_Name ","")&IF(I15="","Missing Contact_Email ","")&IF(J15="","Missing Account_Code ","")&IF(L15="","Missing Verified_By ","")&IF(Q15="Invalid","Invalid Email Format ","")&IF(H15="","Missing Last_Updated ","")) | P15: =IF(N15="Clean","Clean","Flagged for Review") -> Clean | Q15: =IF(I15="","Blank",IF(ISERROR(FIND("@",I15&"")),"Invalid",IF(FIND("@",I15&"")<2,"Invalid",IF(LEN(I15&"")-FIND("@",I15&"")<4,"Invalid","Valid")))) -> Valid
A16: VND-0491 | B16: Vendor Gamma 437 | C16: Legal | D16: Australia | E16: APAC | F16: Active | G16: 45200 | H16: 45489 | I16: vendor.gamma.437@outlook.com | J16: ACC-5514 | K16: Legacy System | L16: Ravi K. | M16: Clean | N16: =IF(OR(B16="",H16="",I16="",J16="",L16="",Q16="Invalid"),"Flagged","Clean") -> Clean | O16: =TRIM(IF(B16="","Missing Vendor_Name ","")&IF(I16="","Missing Contact_Email ","")&IF(J16="","Missing Account_Code ","")&IF(L16="","Missing Verified_By ","")&IF(Q16="Invalid","Invalid Email Format ","")&IF(H16="","Missing Last_Updated ","")) | P16: =IF(N16="Clean","Clean","Flagged for Review") -> Clean | Q16: =IF(I16="","Blank",IF(ISERROR(FIND("@",I16&"")),"Invalid",IF(FIND("@",I16&"")<2,"Invalid",IF(LEN(I16&"")-FIND("@",I16&"")<4,"Invalid","Valid")))) -> Valid
A17: VND-0943 | B17: Vendor Alpha 246 | C17: Marketing | D17: USA | E17: AMER | F17: Active | G17: 44661 | H17: 45002 | I17: vendor.alpha.246@gmail.com | J17: ACC-4559 | K17: Legacy System | L17: James T. | M17: Clean | N17: =IF(OR(B17="",H17="",I17="",J17="",L17="",Q17="Invalid"),"Flagged","Clean") -> Clean | O17: =TRIM(IF(B17="","Missing Vendor_Name ","")&IF(I17="","Missing Contact_Email ","")&IF(J17="","Missing Account_Code ","")&IF(L17="","Missing Verified_By ","")&IF(Q17="Invalid","Invalid Email Format ","")&IF(H17="","Missing Last_Updated ","")) | P17: =IF(N17="Clean","Clean","Flagged for Review") -> Clean | Q17: =IF(I17="","Blank",IF(ISERROR(FIND("@",I17&"")),"Invalid",IF(FIND("@",I17&"")<2,"Invalid",IF(LEN(I17&"")-FIND("@",I17&"")<4,"Invalid","Valid")))) -> Valid
A18: VND-0077 | B18: Vendor Epsilon 15 | C18: Legal | D18: Australia | E18: APAC | F18: Active | G18: 43652 | H18: 43679 | I18: vendor.epsilon.15@corp.net | J18: ACC-5786 | K18: Oracle | M18: Flagged for Review | N18: =IF(OR(B18="",H18="",I18="",J18="",L18="",Q18="Invalid"),"Flagged","Clean") -> Flagged | O18: =TRIM(IF(B18="","Missing Vendor_Name ","")&IF(I18="","Missing Contact_Email ","")&IF(J18="","Missing Account_Code ","")&IF(L18="","Missing Verified_By ","")&IF(Q18="Invalid","Invalid Email Format ","")&IF(H18="","Missing Last_Updated ","")) -> Missing Verified_By | P18: =IF(N18="Clean","Clean","Flagged for Review") -> Flagged for Review | Q18: =IF(I18="","Blank",IF(ISERROR(FIND("@",I18&"")),"Invalid",IF(FIND("@",I18&"")<2,"Invalid",IF(LEN(I18&"")-FIND("@",I18&"")<4,"Invalid","Valid")))) -> Valid
A19: VND-0434 | B19: Vendor Alpha 544 | C19: Legal | D19: India | E19: APAC | F19: Active | G19: 45238 | H19: 45537 | I19: vendor.alpha.544@vendor.com | J19: ACC-9328 | K19: Oracle | M19: Flagged for Review | N19: =IF(OR(B19="",H19="",I19="",J19="",L19="",Q19="Invalid"),"Flagged","Clean") -> Flagged | O19: =TRIM(IF(B19="","Missing Vendor_Name ","")&IF(I19="","Missing Contact_Email ","")&IF(J19="","Missing Account_Code ","")&IF(L19="","Missing Verified_By ","")&IF(Q19="Invalid","Invalid Email Format ","")&IF(H19="","Missing Last_Updated ","")) -> Missing Verified_By | P19: =IF(N19="Clean","Clean","Flagged for Review") -> Flagged for Review | Q19: =IF(I19="","Blank",IF(ISERROR(FIND("@",I19&"")),"Invalid",IF(FIND("@",I19&"")<2,"Invalid",IF(LEN(I19&"")-FIND("@",I19&"")<4,"Invalid","Valid")))) -> Valid
A20: VND-0533 | B20: Vendor Zeta 194 | C20: HR | D20: Australia | E20: APAC | F20: Active | G20: 44489 | H20: 44572 | I20: vendor.zeta.194@vendor.com | J20: ACC-7199 | K20: Oracle | L20: Anita M. | M20: Clean | N20: =IF(OR(B20="",H20="",I20="",J20="",L20="",Q20="Invalid"),"Flagged","Clean") -> Clean | O20: =TRIM(IF(B20="","Missing Vendor_Name ","")&IF(I20="","Missing Contact_Email ","")&IF(J20="","Missing Account_Code ","")&IF(L20="","Missing Verified_By ","")&IF(Q20="Invalid","Invalid Email Format ","")&IF(H20="","Missing Last_Updated ","")) | P20: =IF(N20="Clean","Clean","Flagged for Review") -> Clean | Q20: =IF(I20="","Blank",IF(ISERROR(FIND("@",I20&"")),"Invalid",IF(FIND("@",I20&"")<2,"Invalid",IF(LEN(I20&"")-FIND("@",I20&"")<4,"Invalid","Valid")))) -> Valid
A21: VND-0875 | B21: Vendor Gamma 262 | C21: Marketing | D21: India | E21: APAC | F21: Active | G21: 45134 | H21: 45481 | I21: vendor.gamma.262@yahoo.com | J21: ACC-1965 | K21: Manual Entry | L21: Ravi K. | M21: Clean | N21: =IF(OR(B21="",H21="",I21="",J21="",L21="",Q21="Invalid"),"Flagged","Clean") -> Clean | O21: =TRIM(IF(B21="","Missing Vendor_Name ","")&IF(I21="","Missing Contact_Email ","")&IF(J21="","Missing Account_Code ","")&IF(L21="","Missing Verified_By ","")&IF(Q21="Invalid","Invalid Email Format ","")&IF(H21="","Missing Last_Updated ","")) | P21: =IF(N21="Clean","Clean","Flagged for Review") -> Clean | Q21: =IF(I21="","Blank",IF(ISERROR(FIND("@",I21&"")),"Invalid",IF(FIND("@",I21&"")<2,"Invalid",IF(LEN(I21&"")-FIND("@",I21&"")<4,"Invalid","Valid")))) -> Valid
A22: VND-0724 | B22: Vendor Solutions 565 | C22: IT | D22: UK | E22: EMEA | F22: Active | G22: 44368 | H22: 44596 | I22: vendor.solutions.565@outlook.com | J22: ACC-2515 | K22: Manual Entry | L22: Priya S. | M22: Clean | N22: =IF(OR(B22="",H22="",I22="",J22="",L22="",Q22="Invalid"),"Flagged","Clean") -> Clean | O22: =TRIM(IF(B22="","Missing Vendor_Name ","")&IF(I22="","Missing Contact_Email ","")&IF(J22="","Missing Account_Code ","")&IF(L22="","Missing Verified_By ","")&IF(Q22="Invalid","Invalid Email Format ","")&IF(H22="","Missing Last_Updated ","")) | P22: =IF(N22="Clean","Clean","Flagged for Review") -> Clean | Q22: =IF(I22="","Blank",IF(ISERROR(FIND("@",I22&"")),"Invalid",IF(FIND("@",I22&"")<2,"Invalid",IF(LEN(I22&"")-FIND("@",I22&"")<4,"Invalid","Valid")))) -> Valid
A23: VND-0667 | B23: Vendor Solutions 125 | C23: Legal | D23: India | E23: APAC | F23: Active | G23: 43998 | H23: 44190 | I23: vendor.solutions.125@corp.net | J23: ACC-4027 | K23: SAP | M23: Flagged for Review | N23: =IF(OR(B23="",H23="",I23="",J23="",L23="",Q23="Invalid"),"Flagged","Clean") -> Flagged | O23: =TRIM(IF(B23="","Missing Vendor_Name ","")&IF(I23="","Missing Contact_Email ","")&IF(J23="","Missing Account_Code ","")&IF(L23="","Missing Verified_By ","")&IF(Q23="Invalid","Invalid Email Format ","")&IF(H23="","Missing Last_Updated ","")) -> Missing Verified_By | P23: =IF(N23="Clean","Clean","Flagged for Review") -> Flagged for Review | Q23: =IF(I23="","Blank",IF(ISERROR(FIND("@",I23&"")),"Invalid",IF(FIND("@",I23&"")<2,"Invalid",IF(LEN(I23&"")-FIND("@",I23&"")<4,"Invalid","Valid")))) -> Valid
A24: VND-0602 | B24: Vendor Group 730 | C24: IT | D24: Germany | E24: EMEA | F24: Active | G24: 44270 | H24: 45440 | I24: vendor.group.730@yahoo.com | J24: ACC-2926 | K24: Oracle | L24: Ravi K. | M24: Clean | N24: =IF(OR(B24="",H24="",I24="",J24="",L24="",Q24="Invalid"),"Flagged","Clean") -> Clean | O24: =TRIM(IF(B24="","Missing Vendor_Name ","")&IF(I24="","Missing Contact_Email ","")&IF(J24="","Missing Account_Code ","")&IF(L24="","Missing Verified_By ","")&IF(Q24="Invalid","Invalid Email Format ","")&IF(H24="","Missing Last_Updated ","")) | P24: =IF(N24="Clean","Clean","Flagged for Review") -> Clean | Q24: =IF(I24="","Blank",IF(ISERROR(FIND("@",I24&"")),"Invalid",IF(FIND("@",I24&"")<2,"Invalid",IF(LEN(I24&"")-FIND("@",I24&"")<4,"Invalid","Valid")))) -> Valid
A25: VND-0704 | B25: Vendor Solutions 93 | C25: IT | D25: Germany | E25: EMEA | F25: Active | G25: 44128 | H25: 44488 | I25: vendor.solutions.93@vendor.com | J25: ACC-1399 | K25: Legacy System | L25: James T. | M25: Clean | N25: =IF(OR(B25="",H25="",I25="",J25="",L25="",Q25="Invalid"),"Flagged","Clean") -> Clean | O25: =TRIM(IF(B25="","Missing Vendor_Name ","")&IF(I25="","Missing Contact_Email ","")&IF(J25="","Missing Account_Code ","")&IF(L25="","Missing Verified_By ","")&IF(Q25="Invalid","Invalid Email Format ","")&IF(H25="","Missing Last_Updated ","")) | P25: =IF(N25="Clean","Clean","Flagged for Review") -> Clean | Q25: =IF(I25="","Blank",IF(ISERROR(FIND("@",I25&"")),"Invalid",IF(FIND("@",I25&"")<2,"Invalid",IF(LEN(I25&"")-FIND("@",I25&"")<4,"Invalid","Valid")))) -> Valid
A26: VND-0866 | B26: Vendor Corp 758 | C26: HR | D26: India | E26: APAC | F26: Active | G26: 44894 | H26: 44928 | I26: vendor.corp.758@gmail.com | J26: ACC-7841 | K26: Legacy System | L26: Sarah L. | M26: Clean | N26: =IF(OR(B26="",H26="",I26="",J26="",L26="",Q26="Invalid"),"Flagged","Clean") -> Clean | O26: =TRIM(IF(B26="","Missing Vendor_Name ","")&IF(I26="","Missing Contact_Email ","")&IF(J26="","Missing Account_Code ","")&IF(L26="","Missing Verified_By ","")&IF(Q26="Invalid","Invalid Email Format ","")&IF(H26="","Missing Last_Updated ","")) | P26: =IF(N26="Clean","Clean","Flagged for Review") -> Clean | Q26: =IF(I26="","Blank",IF(ISERROR(FIND("@",I26&"")),"Invalid",IF(FIND("@",I26&"")<2,"Invalid",IF(LEN(I26&"")-FIND("@",I26&"")<4,"Invalid","Valid")))) -> Valid
A27: VND-0912 | B27: Vendor Tech 935 | C27: Marketing | D27: UK | E27: EMEA | F27: Active | G27: 43587 | H27: 43688 | I27: vendor.tech.935@yahoo.com | J27: ACC-5654 | K27: Oracle | L27: Ravi K. | M27: Clean | N27: =IF(OR(B27="",H27="",I27="",J27="",L27="",Q27="Invalid"),"Flagged","Clean") -> Clean | O27: =TRIM(IF(B27="","Missing Vendor_Name ","")&IF(I27="","Missing Contact_Email ","")&IF(J27="","Missing Account_Code ","")&IF(L27="","Missing Verified_By ","")&IF(Q27="Invalid","Invalid Email Format ","")&IF(H27="","Missing Last_Updated ","")) | P27: =IF(N27="Clean","Clean","Flagged for Review") -> Clean | Q27: =IF(I27="","Blank",IF(ISERROR(FIND("@",I27&"")),"Invalid",IF(FIND("@",I27&"")<2,"Invalid",IF(LEN(I27&"")-FIND("@",I27&"")<4,"Invalid","Valid")))) -> Valid
A28: VND-0360 | B28: Vendor Solutions 604 | C28: Marketing | D28: USA | E28: AMER | F28: Active | G28: 44672 | H28: 44737 | I28: vendor.solutions.604@yahoo.com | J28: ACC-1029 | K28: Legacy System | L28: Sarah L. | M28: Clean | N28: =IF(OR(B28="",H28="",I28="",J28="",L28="",Q28="Invalid"),"Flagged","Clean") -> Clean | O28: =TRIM(IF(B28="","Missing Vendor_Name ","")&IF(I28="","Missing Contact_Email ","")&IF(J28="","Missing Account_Code ","")&IF(L28="","Missing Verified_By ","")&IF(Q28="Invalid","Invalid Email Format ","")&IF(H28="","Missing Last_Updated ","")) | P28: =IF(N28="Clean","Clean","Flagged for Review") -> Clean | Q28: =IF(I28="","Blank",IF(ISERROR(FIND("@",I28&"")),"Invalid",IF(FIND("@",I28&"")<2,"Invalid",IF(LEN(I28&"")-FIND("@",I28&"")<4,"Invalid","Valid")))) -> Valid
A29: VND-0315 | B29: Vendor Delta 644 | C29: Legal | D29: USA | E29: AMER | F29: Under Review | G29: 45278 | H29: 45389 | I29: vendor.delta.644@gmail.com | J29: ACC-2646 | K29: Oracle | L29: Priya S. | M29: Clean | N29: =IF(OR(B29="",H29="",I29="",J29="",L29="",Q29="Invalid"),"Flagged","Clean") -> Clean | O29: =TRIM(IF(B29="","Missing Vendor_Name ","")&IF(I29="","Missing Contact_Email ","")&IF(J29="","Missing Account_Code ","")&IF(L29="","Missing Verified_By ","")&IF(Q29="Invalid","Invalid Email Format ","")&IF(H29="","Missing Last_Updated ","")) | P29: =IF(N29="Clean","Clean","Flagged for Review") -> Clean | Q29: =IF(I29="","Blank",IF(ISERROR(FIND("@",I29&"")),"Invalid",IF(FIND("@",I29&"")<2,"Invalid",IF(LEN(I29&"")-FIND("@",I29&"")<4,"Invalid","Valid")))) -> Valid
A30: VND-0763 | B30: Vendor Omega 138 | C30: Finance | D30: Singapore | E30: APAC | F30: Active | G30: 43914 | H30: 44205 | I30: vendor.omega.138@vendor.com | J30: ACC-9837 | K30: Legacy System | L30: James T. | M30: Clean | N30: =IF(OR(B30="",H30="",I30="",J30="",L30="",Q30="Invalid"),"Flagged","Clean") -> Clean | O30: =TRIM(IF(B30="","Missing Vendor_Name ","")&IF(I30="","Missing Contact_Email ","")&IF(J30="","Missing Account_Code ","")&IF(L30="","Missing Verified_By ","")&IF(Q30="Invalid","Invalid Email Format ","")&IF(H30="","Missing Last_Updated ","")) | P30: =IF(N30="Clean","Clean","Flagged for Review") -> Clean | Q30: =IF(I30="","Blank",IF(ISERROR(FIND("@",I30&"")),"Invalid",IF(FIND("@",I30&"")<2,"Invalid",IF(LEN(I30&"")-FIND("@",I30&"")<4,"Invalid","Valid")))) -> Valid
A31: VND-0862 | B31: Vendor Prime 133 | C31: Legal | D31: Australia | E31: APAC | F31: Inactive | G31: 43949 | H31: 44304 | I31: vendor.prime.133@yahoo.com | J31: ACC-8461 | K31: Legacy System | L31: Priya S. | M31: Clean | N31: =IF(OR(B31="",H31="",I31="",J31="",L31="",Q31="Invalid"),"Flagged","Clean") -> Clean | O31: =TRIM(IF(B31="","Missing Vendor_Name ","")&IF(I31="","Missing Contact_Email ","")&IF(J31="","Missing Account_Code ","")&IF(L31="","Missing Verified_By ","")&IF(Q31="Invalid","Invalid Email Format ","")&IF(H31="","Missing Last_Updated ","")) | P31: =IF(N31="Clean","Clean","Flagged for Review") -> Clean | Q31: =IF(I31="","Blank",IF(ISERROR(FIND("@",I31&"")),"Invalid",IF(FIND("@",I31&"")<2,"Invalid",IF(LEN(I31&"")-FIND("@",I31&"")<4,"Invalid","Valid")))) -> Valid
A32: VND-0024 | B32: Vendor Ltd 772 | C32: Marketing | D32: USA | E32: AMER | F32: Active | G32: 45455 | H32: 45701 | I32: vendor.ltd.772@yahoo.com | J32: ACC-7570 | K32: SAP | L32: Ravi K. | M32: Clean | N32: =IF(OR(B32="",H32="",I32="",J32="",L32="",Q32="Invalid"),"Flagged","Clean") -> Clean | O32: =TRIM(IF(B32="","Missing Vendor_Name ","")&IF(I32="","Missing Contact_Email ","")&IF(J32="","Missing Account_Code ","")&IF(L32="","Missing Verified_By ","")&IF(Q32="Invalid","Invalid Email Format ","")&IF(H32="","Missing Last_Updated ","")) | P32: =IF(N32="Clean","Clean","Flagged for Review") -> Clean | Q32: =IF(I32="","Blank",IF(ISERROR(FIND("@",I32&"")),"Invalid",IF(FIND("@",I32&"")<2,"Invalid",IF(LEN(I32&"")-FIND("@",I32&"")<4,"Invalid","Valid")))) -> Valid
A33: VND-0031 | B33: Vendor Delta 519 | C33: Finance | D33: USA | E33: AMER | F33: Under Review | G33: 43747 | H33: 43872 | I33: vendor.delta.519@outlook.com | J33: ACC-5669 | K33: Oracle | L33: James T. | M33: Clean | N33: =IF(OR(B33="",H33="",I33="",J33="",L33="",Q33="Invalid"),"Flagged","Clean") -> Clean | O33: =TRIM(IF(B33="","Missing Vendor_Name ","")&IF(I33="","Missing Contact_Email ","")&IF(J33="","Missing Account_Code ","")&IF(L33="","Missing Verified_By ","")&IF(Q33="Invalid","Invalid Email Format ","")&IF(H33="","Missing Last_Updated ","")) | P33: =IF(N33="Clean","Clean","Flagged for Review") -> Clean | Q33: =IF(I33="","Blank",IF(ISERROR(FIND("@",I33&"")),"Invalid",IF(FIND("@",I33&"")<2,"Invalid",IF(LEN(I33&"")-FIND("@",I33&"")<4,"Invalid","Valid")))) -> Valid
A34: VND-0539 | B34: Vendor Alpha 273 | C34: Marketing | D34: Germany | E34: EMEA | F34: Active | G34: 45391 | H34: 45483 | I34: vendor.alpha.273@yahoo.com | J34: ACC-5097 | K34: Legacy System | L34: Priya S. | M34: Clean | N34: =IF(OR(B34="",H34="",I34="",J34="",L34="",Q34="Invalid"),"Flagged","Clean") -> Clean | O34: =TRIM(IF(B34="","Missing Vendor_Name ","")&IF(I34="","Missing Contact_Email ","")&IF(J34="","Missing Account_Code ","")&IF(L34="","Missing Verified_By ","")&IF(Q34="Invalid","Invalid Email Format ","")&IF(H34="","Missing Last_Updated ","")) | P34: =IF(N34="Clean","Clean","Flagged for Review") -> Clean | Q34: =IF(I34="","Blank",IF(ISERROR(FIND("@",I34&"")),"Invalid",IF(FIND("@",I34&"")<2,"Invalid",IF(LEN(I34&"")-FIND("@",I34&"")<4,"Invalid","Valid")))) -> Valid
A35: VND-0534 | B35: Vendor Beta 433 | C35: Legal | D35: USA | E35: AMER | F35: Active | G35: 44579 | H35: 44724 | I35: noatsign.com | J35: ACC-5404 | K35: Legacy System | L35: Ravi K. | M35: Flagged for Review | N35: =IF(OR(B35="",H35="",I35="",J35="",L35="",Q35="Invalid"),"Flagged","Clean") -> Flagged | O35: =TRIM(IF(B35="","Missing Vendor_Name ","")&IF(I35="","Missing Contact_Email ","")&IF(J35="","Missing Account_Code ","")&IF(L35="","Missing Verified_By ","")&IF(Q35="Invalid","Invalid Email Format ","")&IF(H35="","Missing Last_Updated ","")) -> Invalid Email Format | P35: =IF(N35="Clean","Clean","Flagged for Review") -> Flagged for Review | Q35: =IF(I35="","Blank",IF(ISERROR(FIND("@",I35&"")),"Invalid",IF(FIND("@",I35&"")<2,"Invalid",IF(LEN(I35&"")-FIND("@",I35&"")<4,"Invalid","Valid")))) -> Invalid
A36: VND-0219 | B36: Vendor Solutions 790 | C36: Logistics | D36: India | E36: APAC | F36: Under Review | G36: 44112 | H36: 44320 | J36: ACC-8822 | K36: Oracle | L36: Anita M. | M36: Flagged for Review | N36: =IF(OR(B36="",H36="",I36="",J36="",L36="",Q36="Invalid"),"Flagged","Clean") -> Flagged | O36: =TRIM(IF(B36="","Missing Vendor_Name ","")&IF(I36="","Missing Contact_Email ","")&IF(J36="","Missing Account_Code ","")&IF(L36="","Missing Verified_By ","")&IF(Q36="Invalid","Invalid Email Format ","")&IF(H36="","Missing Last_Updated ","")) -> Missing Contact_Email | P36: =IF(N36="Clean","Clean","Flagged for Review") -> Flagged for Review | Q36: =IF(I36="","Blank",IF(ISERROR(FIND("@",I36&"")),"Invalid",IF(FIND("@",I36&"")<2,"Invalid",IF(LEN(I36&"")-FIND("@",I36&"")<4,"Invalid","Valid")))) -> Blank
A37: VND-0443 | B37: Vendor Group 816 | C37: Marketing | D37: Singapore | E37: APAC | F37: Active | G37: 43658 | H37: 43853 | I37: vendor.group.816@vendor.com | J37: ACC-7825 | K37: Manual Entry | L37: Sarah L. | M37: Clean | N37: =IF(OR(B37="",H37="",I37="",J37="",L37="",Q37="Invalid"),"Flagged","Clean") -> Clean | O37: =TRIM(IF(B37="","Missing Vendor_Name ","")&IF(I37="","Missing Contact_Email ","")&IF(J37="","Missing Account_Code ","")&IF(L37="","Missing Verified_By ","")&IF(Q37="Invalid","Invalid Email Format ","")&IF(H37="","Missing Last_Updated ","")) | P37: =IF(N37="Clean","Clean","Flagged for Review") -> Clean | Q37: =IF(I37="","Blank",IF(ISERROR(FIND("@",I37&"")),"Invalid",IF(FIND("@",I37&"")<2,"Invalid",IF(LEN(I37&"")-FIND("@",I37&"")<4,"Invalid","Valid")))) -> Valid
A38: VND-0089 | B38: Vendor Tech 447 | C38: Legal | D38: Canada | E38: AMER | F38: Active | G38: 43839 | H38: 44079 | I38: vendor.tech.447@outlook.com | J38: ACC-7690 | K38: Manual Entry | L38: Anita M. | M38: Clean | N38: =IF(OR(B38="",H38="",I38="",J38="",L38="",Q38="Invalid"),"Flagged","Clean") -> Clean | O38: =TRIM(IF(B38="","Missing Vendor_Name ","")&IF(I38="","Missing Contact_Email ","")&IF(J38="","Missing Account_Code ","")&IF(L38="","Missing Verified_By ","")&IF(Q38="Invalid","Invalid Email Format ","")&IF(H38="","Missing Last_Updated ","")) | P38: =IF(N38="Clean","Clean","Flagged for Review") -> Clean | Q38: =IF(I38="","Blank",IF(ISERROR(FIND("@",I38&"")),"Invalid",IF(FIND("@",I38&"")<2,"Invalid",IF(LEN(I38&"")-FIND("@",I38&"")<4,"Invalid","Valid")))) -> Valid
A39: VND-0319 | B39: Vendor Solutions 609 | C39: IT | D39: Australia | E39: APAC | F39: Inactive | G39: 43515 | H39: 43699 | I39: vendor.solutions.609@outlook.com | J39: ACC-3162 | K39: Legacy System | L39: Sarah L. | M39: Clean | N39: =IF(OR(B39="",H39="",I39="",J39="",L39="",Q39="Invalid"),"Flagged","Clean") -> Clean | O39: =TRIM(IF(B39="","Missing Vendor_Name ","")&IF(I39="","Missing Contact_Email ","")&IF(J39="","Missing Account_Code ","")&IF(L39="","Missing Verified_By ","")&IF(Q39="Invalid","Invalid Email Format ","")&IF(H39="","Missing Last_Updated ","")) | P39: =IF(N39="Clean","Clean","Flagged for Review") -> Clean | Q39: =IF(I39="","Blank",IF(ISERROR(FIND("@",I39&"")),"Invalid",IF(FIND("@",I39&"")<2,"Invalid",IF(LEN(I39&"")-FIND("@",I39&"")<4,"Invalid","Valid")))) -> Valid
A40: VND-0540 | B40: Vendor Beta 998 | C40: Marketing | D40: Singapore | E40: APAC | F40: Active | G40: 45280 | H40: 45406 | I40: vendor.beta.998@gmail.com | J40: ACC-4263 | K40: Legacy System | M40: Flagged for Review | N40: =IF(OR(B40="",H40="",I40="",J40="",L40="",Q40="Invalid"),"Flagged","Clean") -> Flagged | O40: =TRIM(IF(B40="","Missing Vendor_Name ","")&IF(I40="","Missing Contact_Email ","")&IF(J40="","Missing Account_Code ","")&IF(L40="","Missing Verified_By ","")&IF(Q40="Invalid","Invalid Email Format ","")&IF(H40="","Missing Last_Updated ","")) -> Missing Verified_By | P40: =IF(N40="Clean","Clean","Flagged for Review") -> Flagged for Review | Q40: =IF(I40="","Blank",IF(ISERROR(FIND("@",I40&"")),"Invalid",IF(FIND("@",I40&"")<2,"Invalid",IF(LEN(I40&"")-FIND("@",I40&"")<4,"Invalid","Valid")))) -> Valid
...

Sheet reference_data
A1: Valid_Category | B1: Valid_Status | C1: Country | D1: Expected_Region | E1: Data_Source
A2: IT | B2: Active | C2: India | D2: APAC | E2: Legacy System
A3: Logistics | B3: Inactive | C3: Singapore | D3: APAC | E3: Manual Entry
A4: Finance | B4: Under Review | C4: Australia | D4: APAC | E4: Oracle
A5: HR | C5: USA | D5: AMER | E5: SAP
A6: Operations | C6: Canada | D6: AMER
A7: Legal | C7: UK | D7: EMEA
A8: Marketing | C8: Germany | D8: EMEA

Sheet issue_log
A1: Issue_ID | B1: Vendor_ID | C1: Row_Number | D1: Issue_Type | E1: Count | H1: Issue_Type | I1: Count
D2: Duplicate Vendor_ID | E2: 97 | H2: Duplicate Vendor_ID | I2: =SUMPRODUCT((COUNTIF(validated_data!$A$2:$A$951,validated_data!$A$2:$A$951)>1)*1) -> 0
D3: Missing Vendor_Name | E3: 20 | H3: Missing Vendor_Name | I3: =COUNTBLANK(validated_data!$B$2:$B$951) -> 17
D4: Spaces in Vendor_Name | E4: 19 | H4: Spaces in Vendor_Name | I4: =SUMPRODUCT((LEN(validated_data!$B$2:$B$951)<>LEN(TRIM(validated_data!$B$2:$B$951)))*(validated_data!$B$2:$B$951<>"")) -> 0
D5: Invalid Category | E5: 25 | H5: Invalid Category | I5: 0
D6: Invalid Status | E6: 17 | H6: Invalid Status | I6: 0
D7: Missing Contact_Email | E7: 15 | H7: Missing Contact_Email | I7: =COUNTBLANK(validated_data!$I$2:$I$951) -> 15
D8: Invalid Email Format | E8: 18 | H8: Invalid Email Format | I8: =COUNTIF(validated_data!$Q$2:$Q$951,"Invalid") -> 16
D9: Missing Account_Code | E9: 20 | H9: Missing Account_Code | I9: =COUNTBLANK(validated_data!$J$2:$J$951) -> 17
D10: Missing Region | E10: 10 | H10: Missing Region | I10: =COUNTBLANK(validated_data!$E$2:$E$951) -> 0
D11: Region Mismatch | E11: 15 | H11: Region Mismatch | I11: 0
D12: Missing Last_Updated | E12: 10 | H12: Missing Last_Updated | I12: =COUNTBLANK(validated_data!$H$2:$H$951) -> 9
D13: Missing Verified_by | E13: 179 | H13: Missing Verified_by | I13: =COUNTBLANK(validated_data!$L$2:$L$951) -> 179
D14: Total Issues | E14: =SUM(E2:E13) -> 445 | H14: Total Issues | I14: =SUM(I2:I13) -> 253

Sheet Cleaned_Data
A1: Vendor_ID | B1: Vendor_Name | C1: Category | D1: Country | E1: Region | F1: Status | G1: Onboarding_Date | H1: Last_Updated | I1: Contact_Email | J1: Account_Code | K1: Data_Source | L1: Verified_By | M1: Record_Status
A2: VND-0789 | B2: Vendor Zeta 901 | C2: Marketing | D2: Canada | E2: AMER | F2: Active | G2: 43604 | H2: 43744 | I2: vendor.zeta.901@gmail.com | J2: ACC-9055 | K2: Legacy System | M2: Flagged for Review
A3: VND-0441 | B3: Vendor Epsilon 150 | C3: Marketing | D3: India | E3: APAC | F3: Active | G3: 44674 | H3: 44778 | I3: vendor.epsilon.150@corp.net | J3: ACC-1529 | K3: Manual Entry | L3: James T. | M3: Clean
A4: VND-0140 | B4: Vendor Omega 114 | C4: Finance | D4: Singapore | E4: APAC | F4: Active | G4: 45459 | H4: 45728 | I4: vendor.omega.114@outlook.com | J4: ACC-1744 | K4: Oracle | L4: James T. | M4: Clean
A5: VND-0696 | B5: Vendor Prime 56 | C5: HR | D5: USA | E5: AMER | F5: Active | G5: 45329 | H5: 45420 | I5: vendor.prime.56@vendor.com | J5: ACC-7119 | K5: Oracle | L5: James T. | M5: Clean
A6: VND-0067 | B6: Vendor Zeta 71 | C6: Operations | D6: Singapore | E6: APAC | F6: Active | G6: 45186 | H6: 45436 | I6: vendor.zeta.71@gmail.com | J6: ACC-8102 | K6: Manual Entry | M6: Flagged for Review
A7: VND-0853 | B7: Vendor Beta 524 | C7: Operations | D7: UK | E7: EMEA | F7: Active | G7: 44121 | H7: 44132 | I7: vendor.beta.524@gmail.com | J7: ACC-9846 | K7: Manual Entry | L7: Ravi K. | M7: Clean
A8: VND-0406 | B8: Vendor Services 899 | C8: Finance | D8: UK | E8: EMEA | F8: Active | G8: 45037 | H8: 45294 | I8: vendor.services.899@corp.net | J8: ACC-6015 | K8: Oracle | L8: Priya S. | M8: Clean
A9: VND-0737 | B9: Vendor Omega 652 | C9: Finance | D9: India | E9: APAC | F9: Active | G9: 45635 | H9: 45962 | I9: vendor.omega.652@gmail.com | J9: ACC-9419 | K9: Oracle | M9: Flagged for Review
A10: VND-0458 | B10: Vendor Corp 75 | C10: Finance | D10: Australia | E10: APAC | F10: Active | G10: 44700 | H10: 45010 | I10: vendor.corp.75@gmail.com | J10: ACC-5612 | K10: Legacy System | L10: James T. | M10: Clean
A11: VND-0308 | B11: Vendor Ltd 699 | C11: Marketing | D11: India | E11: APAC | F11: Active | G11: 45348 | H11: 45356 | I11: vendor.ltd.699@gmail.com | J11: ACC-3588 | K11: Legacy System | L11: James T. | M11: Clean
A12: VND-0440 | B12: Vendor Global 110 | C12: IT | D12: Germany | E12: EMEA | F12: Active | G12: 43697 | H12: 43799 | I12: vendor.global.110@outlook.com | J12: ACC-3636 | K12: Manual Entry | M12: Flagged for Review
A13: VND-0068 | B13: Vendor Ltd 849 | C13: IT | D13: Singapore | E13: APAC | F13: Active | G13: 44187 | H13: 44454 | I13: vendor.ltd.849@outlook.com | J13: ACC-9817 | K13: Legacy System | L13: James T. | M13: Clean
A14: VND-0651 | B14: Vendor Tech 494 | C14: Legal | D14: India | E14: APAC | F14: Active | G14: 45622 | H14: 45765 | I14: vendor.tech.494@vendor.com | J14: ACC-9469 | K14: SAP | L14: Sarah L. | M14: Clean
A15: VND-0874 | B15: Vendor Corp 541 | C15: Finance | D15: Germany | E15: EMEA | F15: Active | G15: 43935 | H15: 43985 | I15: vendor.corp.541@corp.net | J15: ACC-3755 | K15: Manual Entry | L15: Ravi K. | M15: Clean
A16: VND-0491 | B16: Vendor Gamma 437 | C16: Legal | D16: Australia | E16: APAC | F16: Active | G16: 45200 | H16: 45489 | I16: vendor.gamma.437@outlook.com | J16: ACC-5514 | K16: Legacy System | L16: Ravi K. | M16: Clean
A17: VND-0943 | B17: Vendor Alpha 246 | C17: Marketing | D17: USA | E17: AMER | F17: Active | G17: 44661 | H17: 45002 | I17: vendor.alpha.246@gmail.com | J17: ACC-4559 | K17: Legacy System | L17: James T. | M17: Clean
A18: VND-0077 | B18: Vendor Epsilon 15 | C18: Legal | D18: Australia | E18: APAC | F18: Active | G18: 43652 | H18: 43679 | I18: vendor.epsilon.15@corp.net | J18: ACC-5786 | K18: Oracle | M18: Flagged for Review
A19: VND-0434 | B19: Vendor Alpha 544 | C19: Legal | D19: India | E19: APAC | F19: Active | G19: 45238 | H19: 45537 | I19: vendor.alpha.544@vendor.com | J19: ACC-9328 | K19: Oracle | M19: Flagged for Review
A20: VND-0533 | B20: Vendor Zeta 194 | C20: HR | D20: Australia | E20: APAC | F20: Active | G20: 44489 | H20: 44572 | I20: vendor.zeta.194@vendor.com | J20: ACC-7199 | K20: Oracle | L20: Anita M. | M20: Clean
A21: VND-0875 | B21: Vendor Gamma 262 | C21: Marketing | D21: India | E21: APAC | F21: Active | G21: 45134 | H21: 45481 | I21: vendor.gamma.262@yahoo.com | J21: ACC-1965 | K21: Manual Entry | L21: Ravi K. | M21: Clean
A22: VND-0724 | B22: Vendor Solutions 565 | C22: IT | D22: UK | E22: EMEA | F22: Active | G22: 44368 | H22: 44596 | I22: vendor.solutions.565@outlook.com | J22: ACC-2515 | K22: Manual Entry | L22: Priya S. | M22: Clean
A23: VND-0667 | B23: Vendor Solutions 125 | C23: Legal | D23: India | E23: APAC | F23: Active | G23: 43998 | H23: 44190 | I23: vendor.solutions.125@corp.net | J23: ACC-4027 | K23: SAP | M23: Flagged for Review
A24: VND-0602 | B24: Vendor Group 730 | C24: IT | D24: Germany | E24: EMEA | F24: Active | G24: 44270 | H24: 45440 | I24: vendor.group.730@yahoo.com | J24: ACC-2926 | K24: Oracle | L24: Ravi K. | M24: Clean
A25: VND-0704 | B25: Vendor Solutions 93 | C25: IT | D25: Germany | E25: EMEA | F25: Active | G25: 44128 | H25: 44488 | I25: vendor.solutions.93@vendor.com | J25: ACC-1399 | K25: Legacy System | L25: James T. | M25: Clean
A26: VND-0866 | B26: Vendor Corp 758 | C26: HR | D26: India | E26: APAC | F26: Active | G26: 44894 | H26: 44928 | I26: vendor.corp.758@gmail.com | J26: ACC-7841 | K26: Legacy System | L26: Sarah L. | M26: Clean
A27: VND-0912 | B27: Vendor Tech 935 | C27: Marketing | D27: UK | E27: EMEA | F27: Active | G27: 43587 | H27: 43688 | I27: vendor.tech.935@yahoo.com | J27: ACC-5654 | K27: Oracle | L27: Ravi K. | M27: Clean
A28: VND-0360 | B28: Vendor Solutions 604 | C28: Marketing | D28: USA | E28: AMER | F28: Active | G28: 44672 | H28: 44737 | I28: vendor.solutions.604@yahoo.com | J28: ACC-1029 | K28: Legacy System | L28: Sarah L. | M28: Clean
A29: VND-0315 | B29: Vendor Delta 644 | C29: Legal | D29: USA | E29: AMER | F29: Under Review | G29: 45278 | H29: 45389 | I29: vendor.delta.644@gmail.com | J29: ACC-2646 | K29: Oracle | L29: Priya S. | M29: Clean
A30: VND-0763 | B30: Vendor Omega 138 | C30: Finance | D30: Singapore | E30: APAC | F30: Active | G30: 43914 | H30: 44205 | I30: vendor.omega.138@vendor.com | J30: ACC-9837 | K30: Legacy System | L30: James T. | M30: Clean
A31: VND-0862 | B31: Vendor Prime 133 | C31: Legal | D31: Australia | E31: APAC | F31: Inactive | G31: 43949 | H31: 44304 | I31: vendor.prime.133@yahoo.com | J31: ACC-8461 | K31: Legacy System | L31: Priya S. | M31: Clean
A32: VND-0024 | B32: Vendor Ltd 772 | C32: Marketing | D32: USA | E32: AMER | F32: Active | G32: 45455 | H32: 45701 | I32: vendor.ltd.772@yahoo.com | J32: ACC-7570 | K32: SAP | L32: Ravi K. | M32: Clean
A33: VND-0031 | B33: Vendor Delta 519 | C33: Finance | D33: USA | E33: AMER | F33: Under Review | G33: 43747 | H33: 43872 | I33: vendor.delta.519@outlook.com | J33: ACC-5669 | K33: Oracle | L33: James T. | M33: Clean
A34: VND-0539 | B34: Vendor Alpha 273 | C34: Marketing | D34: Germany | E34: EMEA | F34: Active | G34: 45391 | H34: 45483 | I34: vendor.alpha.273@yahoo.com | J34: ACC-5097 | K34: Legacy System | L34: Priya S. | M34: Clean
A35: VND-0534 | B35: Vendor Beta 433 | C35: Legal | D35: USA | E35: AMER | F35: Active | G35: 44579 | H35: 44724 | I35: noatsign.com | J35: ACC-5404 | K35: Legacy System | L35: Ravi K. | M35: Flagged for Review
A36: VND-0219 | B36: Vendor Solutions 790 | C36: Logistics | D36: India | E36: APAC | F36: Under Review | G36: 44112 | H36: 44320 | J36: ACC-8822 | K36: Oracle | L36: Anita M. | M36: Flagged for Review
A37: VND-0443 | B37: Vendor Group 816 | C37: Marketing | D37: Singapore | E37: APAC | F37: Active | G37: 43658 | H37: 43853 | I37: vendor.group.816@vendor.com | J37: ACC-7825 | K37: Manual Entry | L37: Sarah L. | M37: Clean
A38: VND-0089 | B38: Vendor Tech 447 | C38: Legal | D38: Canada | E38: AMER | F38: Active | G38: 43839 | H38: 44079 | I38: vendor.tech.447@outlook.com | J38: ACC-7690 | K38: Manual Entry | L38: Anita M. | M38: Clean
A39: VND-0319 | B39: Vendor Solutions 609 | C39: IT | D39: Australia | E39: APAC | F39: Inactive | G39: 43515 | H39: 43699 | I39: vendor.solutions.609@outlook.com | J39: ACC-3162 | K39: Legacy System | L39: Sarah L. | M39: Clean
A40: VND-0540 | B40: Vendor Beta 998 | C40: Marketing | D40: Singapore | E40: APAC | F40: Active | G40: 45280 | H40: 45406 | I40: vendor.beta.998@gmail.com | J40: ACC-4263 | K40: Legacy System | M40: Flagged for Review
...

Sheet summary_dashboard
B2: Vendor Master Data - Quality Validation Report
B3: Validated by: Sushma Date: 01/06/2026
B4: Dataset: Vendor Master Data — 1000 Records
B5: Total Records Received | D5: Final Clean Records | F5: Total Issues Found | H5: Data Quality Score
B6: 1000 | D6: 715 | F6: 445 | H6: 0.753
B7: Issue Summary
B8: Issue Type | C8: Count | D8: Status
B9: Duplicate Vendor_ID | C9: 97 | D9: Resolved
B10: Missing Vendor_Name | C10: 20 | D10: Pending
B11: Spaces in Vendor_Name | C11: 19 | D11: Resolved
B12: Invalid Category | C12: 25 | D12: Resolved
B13: Invalid Status | C13: 17 | D13: Resolved
B14: Missing Contact_Email | C14: 15 | D14: Pending
B15: Invalid Email Format | C15: 18 | D15: Pending
B16: Missing Account_Code | C16: 20 | D16: Pending
B17: Missing Region | C17: 10 | D17: Resolved
B18: Region Mismatch | C18: 15 | D18: Resolved
B19: Missing Last_Updated | C19: 10 | D19: Pending
B20: Missing Verified_by | C20: 179 | D20: Pending
B21: Total Issues | C21: =SUM(C9:C20) -> 445
B22: Recommended Action
B23: Action Required | D23: Priority
B24: Obtain missing vendor names from business | D24: High
B25: Verify and update missing contact emails | D25: High
B26: Assign verifiers to 179 unverified records | D26: Medium
B27: Obtain missing account codes | D27: Medium
B28: Update Last_Updated for inactive records | D28: Low
B54: Recommended Actions
B55: Issues Resolved by Analyst | C55: 192
B56: Pending Business Input | C56: 253
B57: Total Records | C57: 950
B58: Clean Records | C58: 715
B59: Flagged Records | C59: 235
B60: Data Quality Improvement | C60: 0.43
